<?xml version="1.0"?>

<robot name="barrier">
    

    <material name="red">
        <color rgba="1 0 0 1" />
    </material>

    <link name="body_link">

        <inertial>
            <origin rpy="0 0 0" xyz="0 0 0.75" />
            <mass value="100000.0" />
            <inertia ixx="0.0" ixy="0.0" ixz="0.0"
            iyy="0.0" iyz="0.0" izz="0.0" />

        </inertial>

        <visual>        
            <origin rpy="0 0 0" xyz="0 0 0.75" />
            <geometry>
                <cylinder radius="0.15" length="1.5" />
            </geometry>
            <material name="red"/>
        </visual>

        <collision>
            <origin rpy="0 0 0" xyz="0 0 0.75" />
            <geometry>
                <cylinder radius="0.15" length="1.5" />
            </geometry>
        </collision>

    </link>

     <link name="arm_link">
        <inertial>
            <origin rpy="0 0 0" xyz="1.1 0 0.35" />
            <mass value="5.0" />

            <inertia ixx="3.751666667" ixy="0.0" ixz="0.0"
            iyy="3.751666667" iyz="0.0" izz="3.751666667" />
        </inertial>
        <visual>        
            <origin rpy="0 0 0" xyz="1.1 0 0.35" />
            <geometry>
                <box size="3 0.2 0.2" />
            </geometry>
            <material name="red"/>
        </visual>
        <collision>
            <origin rpy="0 0 0" xyz="1.1 0 0.35" />
            <geometry>
             <box size="3 0.2 0.2" />
            </geometry>
        </collision>
    </link>

    <joint name="body_to_arm" type="revolute">
        <parent link="body_link" />
        <child link="arm_link" />
        <dynamics damping="0.0" friction="0.00001" />
        <origin xyz="0 0 0" />
        <axis xyz="0 0 1" />

        <limit lower="-3" upper="3" effort="5.0" velocity="0.5" />
    </joint>

   

    



</robot>